Workbook

Sheet Summary
A1: MASTER PLAN - FOOD DELIVERY MANAGEMENT SYSTEM
A2: Kế hoạch triển khai bám theo food_delivery_db.sql và yêu cầu bài tập lớn | Cập nhật: 26/09/2026
A4: Tiến độ công việc | C4: Đã hoàn thành | E4: Đang thực hiện | G4: Chưa thực hiện | I4: Mốc hiện tại
A5: =AVERAGE(Plan!G5:G11,Plan!G13:G19,Plan!G21:G25,Plan!G28:G35,Plan!G38:G40,Plan!G42:G44,Plan!G46:G48,Plan!G50:G54,Plan!G56:G58) -> 0.43181818 | C5: =COUNTIF(Plan!F5:F11,"Đã hoàn thành")+COUNTIF(Plan!F13:F19,"Đã hoàn thành")+COUNTIF(Plan!F21:F25,"Đã hoàn thành")+COUNTIF(Plan!F28:F35,"Đã hoàn thành")+COUNTIF(Plan!F38:F40,"Đã hoàn thành")+COUNTIF(Plan!F42:F44,"Đã hoàn thành")+COUNTIF(Plan!F46:F48,"Đã hoàn thành")+COUNTIF(Plan!F50:F54,"Đã hoàn thành")+COUNTIF(Plan!F56:F58,"Đã hoàn thành") -> 19 | E5: =COUNTIF(Plan!F5:F11,"Đang thực hiện")+COUNTIF(Plan!F13:F19,"Đang thực hiện")+COUNTIF(Plan!F21:F25,"Đang thực hiện")+COUNTIF(Plan!F28:F35,"Đang thực hiện")+COUNTIF(Plan!F38:F40,"Đang thực hiện")+COUNTIF(Plan!F42:F44,"Đang thực hiện")+COUNTIF(Plan!F46:F48,"Đang thực hiện")+COUNTIF(Plan!F50:F54,"Đang thực hiện")+COUNTIF(Plan!F56:F58,"Đang thực hiện") -> 0 | G5: =COUNTIF(Plan!F5:F11,"Chưa thực hiện")+COUNTIF(Plan!F13:F19,"Chưa thực hiện")+COUNTIF(Plan!F21:F25,"Chưa thực hiện")+COUNTIF(Plan!F28:F35,"Chưa thực hiện")+COUNTIF(Plan!F38:F40,"Chưa thực hiện")+COUNTIF(Plan!F42:F44,"Chưa thực hiện")+COUNTIF(Plan!F46:F48,"Chưa thực hiện")+COUNTIF(Plan!F50:F54,"Chưa thực hiện")+COUNTIF(Plan!F56:F58,"Chưa thực hiện") -> 25 | I5: 3.5/20
A7: Phạm vi và tiến độ thực tế
A8: Backend hiện tại | B8: Node.js + Express, ES modules, MySQL2
A9: Database | B9: MySQL 8.0+ | 66 bảng | 62 index | 8 view | 15 trigger
A10: 4 vai trò | B10: ADMIN | RESTAURANT | SHIPPER | CUSTOMER
A11: Đã triển khai | B11: API foundation, auth/RBAC, restaurant/menu, catalog search, promotion/favorites, cart/checkout, restaurant order state machine, notification and test workflow 2.2-3.5
A12: Còn xác nhận | B12: Còn xác nhận: MySQL end-to-end trên môi trường triển khai, Redis/realtime/GPS, Docker/CI và các nhóm 4.x trở đi
A15: Tiến độ theo nhóm công việc
A16: Nhóm | B16: Tiến độ
A17: 1 - Nền tảng | B17: =Plan!G4 -> 1
A18: 2 - Nhà hàng/menu | B18: =Plan!G12 -> 1
A19: 3 - Đặt món | B19: =Plan!G20 -> 1
A20: 4 - Giao hàng/thanh toán | B20: =Plan!G27 -> 0
A21: 5 - Nhập/xuất/job | B21: =Plan!G37 -> 0
A22: 6 - Bảo mật/giám sát | B22: =Plan!G41 -> 0
A23: 7 - Kiểm thử | B23: =Plan!G45 -> 0
A24: 8 - Bàn giao | B24: =Plan!G49 -> 0
A25: 9 - Nghiệm thu | B25: =Plan!G55 -> 0

Sheet Plan
A1: ID | B1: Công việc | C1: Người chịu trách nhiệm chính | D1: Ước lượng thời gian | E1: Deadline | F1: Trạng thái | G1: Tỉ lệ/Mức độ hoàn thành | H1: Tháng 9/2026 | AC1: Tháng 10/2026 | BH1: Tháng 11/2026
H2: 10 | I2: 11 | J2: 12 | K2: 13 | L2: 14 | M2: 15 | N2: 16 | O2: 17 | P2: 18 | Q2: 19 | R2: 20 | S2: 21 | T2: 22 | U2: 23 | V2: 24 | W2: 25 | X2: 26 | Y2: 27 | Z2: 28 | AA2: 29 | AB2: 30 | AC2: 1 | AD2: 2 | AE2: 3 | AF2: 4 | AG2: 5 | AH2: 6 | AI2: 7 | AJ2: 8 | AK2: 9 | AL2: 10 | AM2: 11 | AN2: 12 | AO2: 13 | AP2: 14 | AQ2: 15 | AR2: 16 | AS2: 17 | AT2: 18 | AU2: 19 | AV2: 20 | AW2: 21 | AX2: 22 | AY2: 23 | AZ2: 24 | BA2: 25 | BB2: 26 | BC2: 27 | BD2: 28 | BE2: 29 | BF2: 30 | BG2: 31 | BH2: 1 | BI2: 2 | BJ2: 3 | BK2: 4 | BL2: 5 | BM2: 6 | BN2: 7 | BO2: 8 | BP2: 9 | BQ2: 10 | BR2: 11
A3: A | B3: Sprint 1 - Core platform, catalog & ordering | C3: Dương | D3: 4w | E3: 46302 | F3: =IF(G3=1,"Đã hoàn thành",IF(G3=0,"Chưa thực hiện","Đang thực hiện")) -> Đã hoàn thành | G3: =AVERAGE(G4,G12,G20) -> 1
A4: 1 | B4: Nền tảng, tài khoản & phân quyền | C4: Dương | D4: 2w | E4: 46283 | F4: =IF(G4=1,"Đã hoàn thành",IF(G4=0,"Chưa thực hiện","Đang thực hiện")) -> Đã hoàn thành | G4: =AVERAGE(G5,G6,G7,G8,G9,G10,G11) -> 1
A5: 1.1 | B5: SRS, ERD, use case/flow và sơ đồ kiến trúc hệ thống | C5: Dương | D5: 1d | E5: 46275 | F5: Đã hoàn thành | G5: 1
A6: 1.2 | B6: SQL schema v1 theo food_delivery_db.sql: 66 bảng, khóa ngoại, index, view và trigger | C6: Dương | D6: 2d | E6: 46275 | F6: Đã hoàn thành | G6: 1
A7: 1.3 | B7: Node.js API foundation: Express, env validation, MySQL pool/transaction, lỗi HTTP, liveness/readiness và graceful shutdown | C7: Dương | D7: 2d | E7: 46276 | F7: Đã hoàn thành | G7: 1
A8: 1.4 | B8: Đăng ký/đăng nhập JWT, access/refresh token, hash mật khẩu, logout, /me và login_history | C8: Dương | D8: 3d | E8: 46277 | F8: Đã hoàn thành | G8: 1
A9: 1.5 | B9: RBAC 4 vai trò, permission theo hành động, reset/email verification, audit log và soft-delete | C9: Dương | D9: 4d | E9: 46281 | F9: Đã hoàn thành | G9: 1
A10: 1.6 | B10: Hồ sơ khách hàng và địa chỉ giao hàng: CRUD, mặc định, xóa mềm, kiểm tra quyền và audit | C10: Dương | D10: 3d | E10: 46280 | F10: Đã hoàn thành | G10: 1
A11: 1.7 | B11: Design system Tailwind CSS thống nhất màu sắc, bố cục, typography, spacing và component cho Food Delivery; UI đăng ký/đăng nhập/hồ sơ 4 vai trò | C11: Dương | D11: 3d | E11: 46283 | F11: Đã hoàn thành | G11: 1
A12: 2 | B12: Nhà hàng & menu | C12: Dương | D12: 3w | E12: 46302 | F12: =IF(G12=1,"Đã hoàn thành",IF(G12=0,"Chưa thực hiện","Đang thực hiện")) -> Đã hoàn thành | G12: =AVERAGE(G13,G14,G15,G16,G17,G18,G19) -> 1
A13: 2.1 | B13: CRUD restaurant_categories, restaurants, operating_hours, restaurant_images; validation, audit, xóa mềm | C13: Dương | D13: 3d | E13: 46287 | F13: Đã hoàn thành | G13: 1
A14: 2.2 | B14: CRUD menus, menu_categories, menu_items; giá gốc/giảm, trạng thái bán và thông tin món | C14: Dương | D14: 4d | E14: 46291 | F14: Đã hoàn thành | G14: 1
A15: 2.3 | B15: Variants, topping_groups, toppings và liên kết topping theo món; kiểm tra min/max lựa chọn | C15: Dương | D15: 3d | E15: 46294 | F15: Đã hoàn thành | G15: 1
A16: 2.4 | B16: Catalog cho khách: tìm kiếm/lọc/sắp xếp/phân trang nhà hàng và menu; lưu search_history | C16: Dương | D16: 2d | E16: 46296 | F16: Đã hoàn thành | G16: 1
A17: 2.5 | B17: Promotions, promotion_usage, banners, favorite restaurants/menu items theo đúng quan hệ SQL | C17: Dương | D17: 2d | E17: 46298 | F17: Đã hoàn thành | G17: 1
A18: 2.6 | B18: Seed dữ liệu mẫu tối thiểu 2.000 bản ghi, kiểm tra khóa ngoại và bộ dữ liệu demo 4 vai trò | C18: Dương | D18: 3d | E18: 46302 | F18: Đã hoàn thành | G18: 1
A19: 2.7 | B19: Quản lý ảnh/icon dùng chung: chọn, upload, thay và xóa; toolbar crop, xoay, zoom, căn khung/reset; aspect-ratio, object-fit và thumbnail đồng đều, không kéo méo ảnh | C19: Dương | D19: 3d | E19: 46302 | F19: Đã hoàn thành | G19: 1
A20: 3 | B20: Giỏ hàng, đặt món & xử lý đơn | C20: Dương | D20: 1.5w | E20: 46302 | F20: =IF(G20=1,"Đã hoàn thành",IF(G20=0,"Chưa thực hiện","Đang thực hiện")) -> Đã hoàn thành | G20: =AVERAGE(G21,G22,G23,G24,G25) -> 1
A21: 3.1 | B21: Giỏ hàng theo khách/nhà hàng: carts, cart_items, cart_item_toppings; cập nhật số lượng và giá snapshot | C21: Dương | D21: 3d | E21: 46294 | F21: Đã hoàn thành | G21: 1
A22: 3.2 | B22: Checkout tạo orders, order_items, order_item_toppings bằng transaction và idempotency key | C22: Dương | D22: 3d | E22: 46297 | F22: Đã hoàn thành | G22: 1
A23: 3.3 | B23: Nhà hàng xác nhận/từ chối, chuẩn bị món; order_status_history và quy tắc chuyển trạng thái | C23: Dương | D23: 2d | E23: 46299 | F23: Đã hoàn thành | G23: 1
A24: 3.4 | B24: UI đặt món: chọn địa chỉ, ghi chú, phí, khuyến mãi và phương thức thanh toán | C24: Dương | D24: 2d | E24: 46301 | F24: Đã hoàn thành | G24: 1
A25: 3.5 | B25: Integration workflow đặt món - xác nhận - chuẩn bị; kiểm tra lỗi nghiệp vụ và audit | C25: Dương | D25: 1d | E25: 46302 | F25: Đã hoàn thành | G25: 1
A26: B | B26: Sprint 2 - Delivery, payment & operations | C26: Dương | D26: 2.5w | E26: 46319 | F26: =IF(G26=1,"Đã hoàn thành",IF(G26=0,"Chưa thực hiện","Đang thực hiện")) -> Chưa thực hiện | G26: =AVERAGE(G27) -> 0
A27: 4 | B27: Shipper, giao hàng, thanh toán & hậu mãi | C27: Dương | D27: 2.5w | E27: 46319 | F27: =IF(G27=1,"Đã hoàn thành",IF(G27=0,"Chưa thực hiện","Đang thực hiện")) -> Chưa thực hiện | G27: =AVERAGE(G28,G29,G30,G31,G32,G33,G34,G35) -> 0
A28: 4.1 | B28: Hồ sơ shipper, giấy tờ, trạng thái sẵn sàng và delivery_assignments; phân quyền nhận đơn | C28: Dương | D28: 3d | E28: 46305 | F28: Chưa thực hiện | G28: 0
A29: 4.2 | B29: Deliveries, delivery_status_history, shipper_locations, delivery_zones; quy trình nhận - giao | C29: Dương | D29: 4d | E29: 46309 | F29: Chưa thực hiện | G29: 0
A30: 4.3 | B30: GPS tracking và cập nhật realtime vị trí/trạng thái giao hàng cho khách, nhà hàng, shipper | C30: Dương | D30: 2d | E30: 46311 | F30: Chưa thực hiện | G30: 0
A31: 4.4 | B31: Payments, payment_transactions, COD; gateway giả lập, retry, callback và xử lý thất bại | C31: Dương | D31: 2d | E31: 46313 | F31: Chưa thực hiện | G31: 0
A32: 4.5 | B32: Invoices, xuất hóa đơn PDF và tra cứu theo order_code; dữ liệu lấy từ snapshot đơn hàng | C32: Dương | D32: 1d | E32: 46314 | F32: Chưa thực hiện | G32: 0
A33: 4.6 | B33: Notifications, preferences, chat theo đơn, review nhà hàng/shipper và support tickets | C33: Dương | D33: 2d | E33: 46316 | F33: Chưa thực hiện | G33: 0
A34: 4.7 | B34: Hủy đơn, refund, ví khách hàng và wallet_transactions; kiểm soát hoàn tiền theo trạng thái | C34: Dương | D34: 2d | E34: 46318 | F34: Chưa thực hiện | G34: 0
A35: 4.8 | B35: Earnings/withdrawals của shipper và settlement/commission của nhà hàng; báo cáo đối soát | C35: Dương | D35: 1d | E35: 46319 | F35: Chưa thực hiện | G35: 0
A36: C | B36: Sprint 3 - Quality, deployment & handover | C36: Dương | D36: 2.5w | E36: 46337 | F36: =IF(G36=1,"Đã hoàn thành",IF(G36=0,"Chưa thực hiện","Đang thực hiện")) -> Chưa thực hiện | G36: =AVERAGE(G37,G41,G45,G49,G55) -> 0
A37: 5 | B37: Nhập/xuất, báo cáo & tác vụ nền | C37: Dương | D37: 1w | E37: 46324 | F37: =IF(G37=1,"Đã hoàn thành",IF(G37=0,"Chưa thực hiện","Đang thực hiện")) -> Chưa thực hiện | G37: =AVERAGE(G38,G39,G40) -> 0
A38: 5.1 | B38: Import Excel/CSV cho nhà hàng, menu và dữ liệu demo; lưu import_jobs và kết quả từng dòng | C38: Dương | D38: 2d | E38: 46321 | F38: Chưa thực hiện | G38: 0
A39: 5.2 | B39: Export CSV/Excel/PDF cho đơn, doanh thu, shipper và restaurant settlement; lưu export_jobs | C39: Dương | D39: 2d | E39: 46323 | F39: Chưa thực hiện | G39: 0
A40: 5.3 | B40: Background jobs cho mail, export lớn và dọn token; retry, trạng thái job và log lỗi | C40: Dương | D40: 1d | E40: 46324 | F40: Chưa thực hiện | G40: 0
...

Sheet Ha tang
A1: HẠ TẦNG VÀ CÔNG NGHỆ - FOOD DELIVERY
A3: STT | B3: Hạng mục | C3: Công nghệ / phiên bản | D3: Hiện trạng / ghi chú
A4: 1 | B4: Backend | C4: Node.js 20+ / Express 4 / ES modules | D4: Đã có env validation, MySQL pool/transaction, lỗi HTTP và graceful shutdown
A5: 2 | B5: Database | C5: MySQL 8.0+ / food_delivery_db.sql | D5: 66 bảng, 62 index, 8 view, 15 trigger; là nguồn dữ liệu chuẩn
A6: 3 | B6: Frontend | C6: HTML, JavaScript, Tailwind CSS + design tokens dùng chung | D6: Đã có UI ordering/catalog/checkout cho customer, queue xử lý đơn cho restaurant và design tokens dùng chung
A7: 4 | B7: Auth | C7: JWT access/refresh + node:crypto PBKDF2/HMAC | D7: Đã có register/login/logout/me, login_history, refresh token hash, reset mật khẩu và xác thực email
A8: 5 | B8: Phân quyền | C8: RBAC ADMIN/RESTAURANT/SHIPPER/CUSTOMER | D8: Đã kiểm tra role và permission từ database, phủ middleware bằng unit test
A9: 6 | B9: Audit | C9: audit_logs + request audit middleware | D9: Lưu thao tác web vào database để mở lại trong hệ thống
A10: 7 | B10: Cache / realtime | C10: Redis + WebSocket/Socket.IO | D10: Đưa vào Sprint 3; phục vụ catalog, GPS và trạng thái đơn
A11: 8 | B11: Job queue | C11: background_jobs + worker | D11: Đưa vào Sprint 3; mail, export lớn, dọn token
A12: 9 | B12: Mail test | C12: MailHog | D12: Dùng trong Docker Compose khi làm notification
A13: 10 | B13: PDF / report | C13: PDFKit + query từ các view báo cáo SQL | D13: Đưa vào Sprint 2-3
A14: 11 | B14: Import / export | C14: CSV/Excel + import_jobs/export_jobs | D14: Đưa vào Sprint 3
A15: 12 | B15: API docs | C15: OpenAPI/Swagger + Postman | D15: Đưa vào hạng mục 8.3
... A20: 17 | B20: Media | C20: Image picker/editor + xử lý thumbnail | D20: Đã hoàn thành trong 2.7: image picker/editor, crop khung vuông, rotate/zoom/reset, thumbnail object-fit và upload API

Sheet SQL coverage
A1: MA TRẬN BÁM SÁT DATABASE - food_delivery_db.sql
A3: Nhóm dữ liệu | B3: Bảng SQL | C3: Vai trò trong hệ thống | D3: Plan ID | E3: Trạng thái hiện tại | F3: Ghi chú
A4: Identity & access | B4: roles | C4: Vai trò hệ thống | D4: 1.5 | E4: Đã hoàn thành | F4: Đã dùng cho auth/RBAC và middleware permission
A5: Identity & access | B5: users | C5: Tài khoản dùng chung cho 4 vai trò | D5: 1.4, 1.5, 2.7 | E5: Đã hoàn thành | F5: Upload ảnh JPEG/PNG/WebP, lưu an toàn, editor crop khung vuông/rotate/zoom/reset và object-fit.
A6: Identity & access | B6: permissions | C6: Danh sách quyền theo hành động | D6: 1.5 | E6: Đã hoàn thành | F6: Đã dùng cho permission theo hành động
A7: Identity & access | B7: role_permissions | C7: Gán quyền cho role | D7: 1.5 | E7: Đã hoàn thành | F7: Đã dùng cho gán quyền role
A8: Identity & access | B8: customer_profiles | C8: Hồ sơ khách hàng | D8: 1.6 | E8: Đã hoàn thành | F8: Đã có API hồ sơ khách hàng, audit và test service
A9: Identity & access | B9: customer_addresses | C9: Địa chỉ giao hàng | D9: 1.6 | E9: Đã hoàn thành | F9: Đã có CRUD địa chỉ, default/soft-delete/audit và test service
A10: Restaurant & menu | B10: restaurant_categories | C10: Danh mục nhà hàng | D10: 2.1 | E10: Đã hoàn thành | F10: Đã hoàn tất API Node.js và test service/controller ở hạng mục 2.1
A11: Restaurant & menu | B11: restaurants | C11: Thông tin nhà hàng | D11: 2.1 | E11: Đã hoàn thành | F11: Đã hoàn tất API Node.js và test service/controller ở hạng mục 2.1
A12: Restaurant & menu | B12: restaurant_operating_hours | C12: Giờ hoạt động | D12: 2.1 | E12: Đã hoàn thành | F12: Đã hoàn tất API Node.js và test service/controller ở hạng mục 2.1
A13: Restaurant & menu | B13: restaurant_images | C13: Ảnh logo/cover/gallery | D13: 2.1, 2.7 | E13: Đã hoàn thành | F13: Upload ảnh JPEG/PNG/WebP, lưu an toàn, editor crop khung vuông/rotate/zoom/reset và object-fit.
A14: Restaurant & menu | B14: menus | C14: Menu theo nhà hàng | D14: 2.2 | E14: Đã hoàn thành | F14: Menu API: CRUD menu/category/item, validation giá và trạng thái, soft-delete; đã gắn owner RBAC.
... A20: Restaurant & menu | B20: menu_item_topping_groups | C20: Liên kết món - nhóm topping | D20: 2.3 | E20: Đã hoàn thành | F20: Variant/topping API, liên kết topping theo món và kiểm tra min/max lựa chọn.
A21: Shipper | B21: shipper_profiles | C21: Hồ sơ và trạng thái shipper | D21: 4.1 | E21: Chưa thực hiện
A22: Shipper | B22: shipper_documents | C22: Giấy tờ shipper | D22: 4.1 | E22: Chưa thực hiện
A23: Cart & ordering | B23: carts | C23: Giỏ theo khách và nhà hàng | D23: 3.1 | E23: Đã hoàn thành | F23: Cart theo customer/restaurant, cập nhật quantity/topping/note và snapshot giá.
A24: Cart & ordering | B24: cart_items | C24: Món trong giỏ | D24: 3.1 | E24: Đã hoàn thành | F24: Cart theo customer/restaurant, cập nhật quantity/topping/note và snapshot giá.
A25: Cart & ordering | B25: cart_item_toppings | C25: Topping trong giỏ | D25: 3.1 | E25: Đã hoàn thành | F25: Cart theo customer/restaurant, cập nhật quantity/topping/note và snapshot giá.
A26: Cart & ordering | B26: orders | C26: Đơn hàng và snapshot địa chỉ | D26: 3.2 | E26: Đã hoàn thành | F26: Checkout transaction tạo order/order items/payment, tính lại phí/giá server và idempotency key.
A27: Cart & ordering | B27: order_items | C27: Chi tiết món trong đơn | D27: 3.2 | E27: Đã hoàn thành | F27: Checkout transaction tạo order/order items/payment, tính lại phí/giá server và idempotency key.
A28: Cart & ordering | B28: order_item_toppings | C28: Topping trong đơn | D28: 3.2 | E28: Đã hoàn thành | F28: Checkout transaction tạo order/order items/payment, tính lại phí/giá server và idempotency key.
A29: Cart & ordering | B29: order_status_history | C29: Lịch sử trạng thái đơn | D29: 3.3 | E29: Đã hoàn thành | F29: Restaurant state machine PENDING -> CONFIRMED -> PREPARING -> READY_FOR_PICKUP và reject.
A30: Delivery | B30: deliveries | C30: Thông tin chuyến giao | D30: 4.2 | E30: Chưa thực hiện
A31: Delivery | B31: delivery_status_history | C31: Lịch sử giao hàng | D31: 4.2 | E31: Chưa thực hiện
A32: Delivery | B32: shipper_locations | C32: Vị trí GPS shipper | D32: 4.2, 4.3 | E32: Chưa thực hiện
A33: Delivery | B33: delivery_assignments | C33: Phân công đơn giao | D33: 4.1, 4.2 | E33: Chưa thực hiện
A34: Payment & invoice | B34: payments | C34: Thanh toán của đơn | D34: 4.4 | E34: Chưa thực hiện
A35: Payment & invoice | B35: payment_transactions | C35: Giao dịch/callback thanh toán | D35: 4.4 | E35: Chưa thực hiện
A36: Payment & invoice | B36: cod_transactions | C36: Thu hộ COD | D36: 4.4 | E36: Chưa thực hiện
A37: Payment & invoice | B37: invoices | C37: Hóa đơn | D37: 4.5 | E37: Chưa thực hiện
A38: Promotion & engagement | B38: promotions | C38: Mã/chiến dịch khuyến mãi | D38: 2.5 | E38: Đã hoàn thành | F38: Promotion CRUD/validation/usage, banners public và favorites restaurant/menu item.
A39: Promotion & engagement | B39: promotion_usage | C39: Lượt sử dụng khuyến mãi | D39: 2.5 | E39: Đã hoàn thành | F39: Promotion CRUD/validation/usage, banners public và favorites restaurant/menu item.
A40: Promotion & engagement | B40: restaurant_reviews | C40: Đánh giá nhà hàng | D40: 4.6 | E40: Chưa thực hiện
A41: Promotion & engagement | B41: shipper_reviews | C41: Đánh giá shipper | D41: 4.6 | E41: Chưa thực hiện
A42: Promotion & engagement | B42: favorite_restaurants | C42: Nhà hàng yêu thích | D42: 2.5 | E42: Đã hoàn thành | F42: Promotion CRUD/validation/usage, banners public và favorites restaurant/menu item.
A43: Promotion & engagement | B43: favorite_menu_items | C43: Món ăn yêu thích | D43: 2.5 | E43: Đã hoàn thành | F43: Promotion CRUD/validation/usage, banners public và favorites restaurant/menu item.
A44: Communication | B44: notifications | C44: Thông báo in-app/email | D44: 4.6, 5.3 | E44: Chưa thực hiện
A45: Communication | B45: notification_preferences | C45: Tùy chọn nhận thông báo | D45: 4.6 | E45: Chưa thực hiện
A46: Communication | B46: chat_sessions | C46: Phiên chat theo đơn | D46: 4.6 | E46: Chưa thực hiện
...

Sheet Yeu cau
A1: MA TRẬN ĐÁP ỨNG YÊU CẦU CHUNG VÀ ĐỀ TÀI FOOD DELIVERY
A3: Nhóm yêu cầu | B3: Nội dung cần đáp ứng | C3: Plan ID | D3: Mức đáp ứng trong kế hoạch | E3: Căn cứ SQL / bàn giao
A4: Tài khoản | B4: Đăng ký/đăng nhập, JWT, refresh token, reset mật khẩu | C4: 1.4, 1.5 | D4: Đã hoàn thành nền tảng | E4: users, refresh_tokens, password_reset_tokens, login_history
A5: Phân quyền | B5: Ít nhất 3 vai trò; đề tài dùng ADMIN/RESTAURANT/SHIPPER/CUSTOMER | C5: 1.5, 1.7 | D5: Đã hoàn thành nền tảng | E5: roles, permissions, role_permissions
A6: CRUD & tra cứu | B6: CRUD có tìm kiếm, lọc, sắp xếp, phân trang | C6: 2.1-2.5, 3.1-3.4 | D6: Đã đưa vào kế hoạch | E6: restaurant_*, menu_*, carts, orders
A7: Ảnh & icon | B7: Chọn/upload/thay/xóa; toolbar crop, xoay, zoom, căn khung/reset; hiển thị đồng đều và không méo ảnh | C7: 2.7, 6.1 | D7: Đã đưa vào kế hoạch | E7: restaurant_images, restaurant_categories.image_url, menu_items.image_url, users.avatar_url, banners.image_url
A8: Giao diện & design system | B8: Tailwind CSS, token màu, bố cục, typography, spacing và component dùng chung; responsive theo nghiệp vụ giao đồ ăn | C8: 1.7, 2.7, 3.4 | D8: Đã hoàn thành nền tảng | E8: UI tĩnh đăng nhập/đăng ký/hồ sơ cho 4 vai trò; mở rộng workflow ở 2.7 và 3.4
A9: Import/export/PDF | B9: Excel/CSV, hóa đơn PDF, báo cáo và job lớn | C9: 4.5, 5.1-5.3 | D9: Đã đưa vào kế hoạch | E9: invoices, import_jobs, export_jobs, background_jobs
A10: Audit & dữ liệu | B10: Ai làm gì, lúc nào; soft-delete; snapshot/versioning cơ bản | C10: 1.5, 1.6, 3.2, 6.3 | D10: Đang làm | E10: Đã phủ auth/profile/address/restaurant; order snapshots và system audit nâng cấp ở 3.2/6.3
A11: Thông báo & job | B11: Email/in-app notification, hàng đợi tác vụ lâu | C11: 4.6, 5.3 | D11: Đã đưa vào kế hoạch | E11: notifications, notification_preferences, background_jobs
A12: API tài liệu | B12: OpenAPI/Swagger đầy đủ và Postman collection | C12: 8.3 | D12: Đã đưa vào kế hoạch | E12: Toàn bộ API
A13: Kiểm thử | B13: Unit service, integration API, E2E, coverage mục tiêu 30-40% | C13: 3.5, 7.1-7.3, 9.1 | D13: Đang làm | E13: Đã có 54 kiểm tra foundation, auth, RBAC, customer/address, validation, service và controller nhà hàng; integration/E2E làm tiếp
A14: Triển khai | B14: Docker Compose và CI/CD build-test-deploy | C14: 8.1, 8.2 | D14: Đã đưa vào kế hoạch | E14: API + MySQL + Redis + MailHog
... A19: Realtime/GPS | B19: Realtime thay đổi trạng thái và GPS tracking | C19: 4.2, 4.3, 6.2, 9.1 | D19: Đã đưa vào kế hoạch | E19: delivery_status_history, shipper_locations
